================================================================================
LOADING VILLAGE DATA - DISTRICT-BASED ANALYSIS
================================================================================

Dataset loaded successfully!
  Total villages: 900
  Total districts: 30
  Villages per district: 30

================================================================================
1. DISTRICT GEOGRAPHIC DISTRIBUTION
================================================================================

All 30 Districts (30 villages each):
  Nyarugenge: 30 villages
  Gasabo: 30 villages
  Kicukiro: 30 villages
  Nyanza: 30 villages
  Gisagara: 30 villages
  Nyaruguru: 30 villages
  Huye: 30 villages
  Nyamagabe: 30 villages
  Ruhango: 30 villages
  Muhanga: 30 villages
  Kamonyi: 30 villages
  Karongi: 30 villages
  Rutsiro: 30 villages
  Rubavu: 30 villages
  Nyabihu: 30 villages
  Ngororero: 30 villages
  Rusizi: 30 villages
  Nyamasheke: 30 villages
  Rulindo: 30 villages
  Gakenke: 30 villages
  Musanze: 30 villages
  Burera: 30 villages
  Gicumbi: 30 villages
  Rwamagana: 30 villages
  Nyagatare: 30 villages
  Gatsibo: 30 villages
  Kayonza: 30 villages
  Kirehe: 30 villages
  Ngoma: 30 villages
  Bugesera: 30 villages
Traceback (most recent call last):
  File "/usr/lib/python3/dist-packages/pandas/core/indexes/base.py", line 3791, in get_loc
    return self._engine.get_loc(casted_key)
           ^^^^^^^^^^^^^^^^^^^^^^^^^^^^^^^^
  File "pandas/_libs/index.pyx", line 152, in pandas._libs.index.IndexEngine.get_loc
  File "pandas/_libs/index.pyx", line 181, in pandas._libs.index.IndexEngine.get_loc
  File "pandas/_libs/hashtable_class_helper.pxi", line 7080, in pandas._libs.hashtable.PyObjectHashTable.get_item
  File "pandas/_libs/hashtable_class_helper.pxi", line 7088, in pandas._libs.hashtable.PyObjectHashTable.get_item
KeyError: 'S1Q1_Location'

The above exception was the direct cause of the following exception:

Traceback (most recent call last):
  File "/home/micro/Nisr 2021 food security/Microdata/village/district_based_analysis.py", line 38, in <module>
    location_by_district = pd.crosstab(df['S0_D_Dist'], df['S1Q1_Location'], normalize='index') * 100
                                                        ~~^^^^^^^^^^^^^^^^^
  File "/usr/lib/python3/dist-packages/pandas/core/frame.py", line 3893, in __getitem__
    indexer = self.columns.get_loc(key)
              ^^^^^^^^^^^^^^^^^^^^^^^^^
  File "/usr/lib/python3/dist-packages/pandas/core/indexes/base.py", line 3798, in get_loc
    raise KeyError(key) from err
KeyError: 'S1Q1_Location'
